Workbook

Sheet Dashboard
A1: v4 DECISION ENGINE — COMMAND CENTER
A3: SYSTEM OVERVIEW | D3: PHASE PIPELINE | G3: COST SUMMARY
A4: Total Agents | B4: =COUNTA('Agent Routing'!A2:A9) -> 8 | D4: P0: Classify | E4: ='Agent Routing'!C2 -> claude-haiku-4-5 | G4: Cost/Project (cached) | H4: ='Cost Model'!I10 -> 0.2256
A5: Total Frameworks | B5: =COUNTA('Framework Map'!A2:A31) -> 30 | D5: P1: Hypotheses | E5: ='Agent Routing'!C3 -> claude-opus-4-6 | G5: Cost/Project (no cache) | H5: ='Cost Model'!J10 -> 0.5745
A6: Convergence Gates | B6: =COUNTA(Gates!A2:A7) -> 6 | D6: P1b: Gauntlet | E6: ='Agent Routing'!C4 -> claude-sonnet-4-6 | G6: Cache Savings % | H6: ='Cost Model'!K10 -> 0.6073107
A7: Re-entry Triggers | B7: =COUNTA('Re-entry'!A2:A9) -> 8 | D7: P2: Audit | E7: ='Agent Routing'!C5 -> claude-sonnet-4-6 | G7: Solo Monthly Cost | H7: ='Cost Model'!I14 -> 1.7235
A8: Active Projects | B8: =COUNTIF('Project Log'!L2:L31,"Active") -> 0 | D8: P3: Strategy | E8: ='Agent Routing'!C6 -> claude-opus-4-6 | G8: SaaS Monthly (100u) | H8: ='Cost Model'!I17 -> 0
A9: Avg Brier Score | B9: =IFERROR(AVERAGE('Meta-Learning'!F5:F54),"-") -> - | D9: P3b: SQI | E9: ='Agent Routing'!C7 -> claude-sonnet-4-6
D10: P4: Monitor | E10: ='Agent Routing'!C8 -> claude-sonnet-4-6
D11: P5: Report | E11: ='Agent Routing'!C9 -> claude-sonnet-4-6
A13: PIPELINE SUMMARY | D13: REVENUE (from P&L)
A14: Total Prospects | B14: =COUNTA(Pipeline!A2:A50)-COUNTBLANK(Pipeline!A2:A50) -> -49 | D14: Month 1 | E14: ='Revenue Forecast'!B18 -> 200
A15: Discovery Calls | B15: =COUNTIF(Pipeline!F2:F50,"Discovery") -> 0 | D15: Month 2 | E15: ='Revenue Forecast'!C18 -> 200
A16: Proposals Sent | B16: =COUNTIF(Pipeline!F2:F50,"Proposal") -> 0 | D16: Month 3 | E16: ='Revenue Forecast'!D18 -> 200
A17: Won | B17: =COUNTIF(Pipeline!F2:F50,"Won") -> 0 | D17: Q1 Total | E17: ='Revenue Forecast'!E18 -> 200
A18: Pipeline Value | B18: =SUMIF(Pipeline!F2:F50,"<>Lost",Pipeline!G2:G50) -> 0 | D18: Monthly Costs | E18: ='Revenue Forecast'!B25 -> 0
A19: Win Rate | B19: =IFERROR(COUNTIF(Pipeline!F2:F50,"Won")/(COUNTIF(Pipeline!F2:F50,"Won")+COUNTIF(Pipeline!F2:F50,"Lost")),"-") -> - | D19: Net Q1 | E19: ='Revenue Forecast'!E27 -> 0

Sheet Agent Routing
A1: Phase | B1: Agent Name | C1: Primary Model | D1: Fallback Model | E1: Alt Provider | F1: Max Tokens | G1: Temperature | H1: Thinking Budget | I1: Input $/MTok | J1: Output $/MTok | K1: Priority
A2: P0: Classify | B2: ClassifyAgent | C2: claude-haiku-4-5 | D2: claude-sonnet-4-6 | E2: gpt-4.1-nano (legacy) | F2: 2000 | G2: 0.2 | I2: 1 | J2: 5 | K2: Speed
A3: P1: Hypotheses | B3: HypothesesAgent | C3: claude-opus-4-6 | D3: claude-sonnet-4-6 | E3: gpt-4.1 (legacy) | F3: 4000 | G3: 0.4 | H3: 15000 | I3: 5 | J3: 25 | K3: Depth
A4: P1b: Gauntlet | B4: GauntletAgent | C4: claude-sonnet-4-6 | D4: claude-haiku-4-5 | E4: gpt-4.1-mini (legacy) | F4: 4000 | G4: 0.3 | H4: 10000 | I4: 3 | J4: 15 | K4: Rigor
A5: P2: Audit | B5: AuditAgent | C5: claude-sonnet-4-6 | D5: claude-haiku-4-5 | E5: gpt-4o | F5: 4000 | G5: 0.3 | H5: 5000 | I5: 3 | J5: 15 | K5: Accuracy
A6: P3: Strategy | B6: StrategyAgent | C6: claude-opus-4-6 | D6: claude-sonnet-4-6 | E6: gpt-4.1 (legacy) | F6: 6000 | G6: 0.4 | H6: 20000 | I6: 5 | J6: 25 | K6: Depth
A7: P3b: SQI | B7: SQIAgent | C7: claude-sonnet-4-6 | D7: claude-haiku-4-5 | E7: gpt-4.1-mini (legacy) | F7: 4000 | G7: 0.2 | H7: 5000 | I7: 3 | J7: 15 | K7: Objectivity
A8: P4: Monitor | B8: MonitorAgent | C8: claude-sonnet-4-6 | D8: claude-haiku-4-5 | E8: gpt-4o-mini | F8: 3000 | G8: 0.3 | I8: 3 | J8: 15 | K8: Structure
A9: P5: Report | B9: ReportAgent | C9: claude-sonnet-4-6 | D9: claude-haiku-4-5 | E9: gpt-4.1 (legacy) | F9: 8000 | G9: 0.3 | H9: 10000 | I9: 3 | J9: 15 | K9: Quality
A11: Source: Anthropic pricing page, April 2026. Opus 4.6: $5/$25 MTok. Sonnet 4.6: $3/$15. Haiku 4.5: $1/$5.

Sheet Cost Model
A1: Phase | B1: Model | C1: Avg Input Tok | D1: Avg Output Tok | E1: Input $/MTok | F1: Output $/MTok | G1: Cache % | H1: Batch Disc % | I1: Cost/Call (cached) | J1: Cost/Call (no cache) | K1: Savings
A2: ='Agent Routing'!A2 -> P0: Classify | B2: ='Agent Routing'!C2 -> claude-haiku-4-5 | C2: 3000 | D2: 1500 | E2: ='Agent Routing'!I2 -> 1 | F2: ='Agent Routing'!J2 -> 5 | G2: 0.9 | H2: 0.5 | I2: =(C2*E2*(1-G2)*(1-H2)/1000000)+(D2*F2*(1-H2)/1000000) -> 0.0039 | J2: =(C2*E2/1000000)+(D2*F2/1000000) -> 0.0105 | K2: =1-I2/J2 -> 0.62857143
A3: ='Agent Routing'!A3 -> P1: Hypotheses | B3: ='Agent Routing'!C3 -> claude-opus-4-6 | C3: 5000 | D3: 3000 | E3: ='Agent Routing'!I3 -> 5 | F3: ='Agent Routing'!J3 -> 25 | G3: 0.9 | H3: 0.5 | I3: =(C3*E3*(1-G3)*(1-H3)/1000000)+(D3*F3*(1-H3)/1000000) -> 0.03875 | J3: =(C3*E3/1000000)+(D3*F3/1000000) -> 0.1 | K3: =1-I3/J3 -> 0.6125
A4: ='Agent Routing'!A4 -> P1b: Gauntlet | B4: ='Agent Routing'!C4 -> claude-sonnet-4-6 | C4: 4000 | D4: 3000 | E4: ='Agent Routing'!I4 -> 3 | F4: ='Agent Routing'!J4 -> 15 | G4: 0.9 | H4: 0.5 | I4: =(C4*E4*(1-G4)*(1-H4)/1000000)+(D4*F4*(1-H4)/1000000) -> 0.0231 | J4: =(C4*E4/1000000)+(D4*F4/1000000) -> 0.057 | K4: =1-I4/J4 -> 0.59473684
A5: ='Agent Routing'!A5 -> P2: Audit | B5: ='Agent Routing'!C5 -> claude-sonnet-4-6 | C5: 6000 | D5: 3000 | E5: ='Agent Routing'!I5 -> 3 | F5: ='Agent Routing'!J5 -> 15 | G5: 0.9 | H5: 0.5 | I5: =(C5*E5*(1-G5)*(1-H5)/1000000)+(D5*F5*(1-H5)/1000000) -> 0.0234 | J5: =(C5*E5/1000000)+(D5*F5/1000000) -> 0.063 | K5: =1-I5/J5 -> 0.62857143
A6: ='Agent Routing'!A6 -> P3: Strategy | B6: ='Agent Routing'!C6 -> claude-opus-4-6 | C6: 8000 | D6: 4000 | E6: ='Agent Routing'!I6 -> 5 | F6: ='Agent Routing'!J6 -> 25 | G6: 0.9 | H6: 0.5 | I6: =(C6*E6*(1-G6)*(1-H6)/1000000)+(D6*F6*(1-H6)/1000000) -> 0.052 | J6: =(C6*E6/1000000)+(D6*F6/1000000) -> 0.14 | K6: =1-I6/J6 -> 0.62857143
A7: ='Agent Routing'!A7 -> P3b: SQI | B7: ='Agent Routing'!C7 -> claude-sonnet-4-6 | C7: 4000 | D7: 3000 | E7: ='Agent Routing'!I7 -> 3 | F7: ='Agent Routing'!J7 -> 15 | G7: 0.9 | H7: 0.5 | I7: =(C7*E7*(1-G7)*(1-H7)/1000000)+(D7*F7*(1-H7)/1000000) -> 0.0231 | J7: =(C7*E7/1000000)+(D7*F7/1000000) -> 0.057 | K7: =1-I7/J7 -> 0.59473684
A8: ='Agent Routing'!A8 -> P4: Monitor | B8: ='Agent Routing'!C8 -> claude-sonnet-4-6 | C8: 3000 | D8: 2000 | E8: ='Agent Routing'!I8 -> 3 | F8: ='Agent Routing'!J8 -> 15 | G8: 0.9 | H8: 0.5 | I8: =(C8*E8*(1-G8)*(1-H8)/1000000)+(D8*F8*(1-H8)/1000000) -> 0.01545 | J8: =(C8*E8/1000000)+(D8*F8/1000000) -> 0.039 | K8: =1-I8/J8 -> 0.60384615
A9: ='Agent Routing'!A9 -> P5: Report | B9: ='Agent Routing'!C9 -> claude-sonnet-4-6 | C9: 6000 | D9: 6000 | E9: ='Agent Routing'!I9 -> 3 | F9: ='Agent Routing'!J9 -> 15 | G9: 0.9 | H9: 0.5 | I9: =(C9*E9*(1-G9)*(1-H9)/1000000)+(D9*F9*(1-H9)/1000000) -> 0.0459 | J9: =(C9*E9/1000000)+(D9*F9/1000000) -> 0.108 | K9: =1-I9/J9 -> 0.575
A10: TOTAL PER PROJECT | I10: =SUM(I2:I9) -> 0.2256 | J10: =SUM(J2:J9) -> 0.5745 | K10: =1-I10/J10 -> 0.6073107
A12: SOLO CONSULTING SCENARIO
A13: Projects/month | B13: 3
A14: Monthly API cost | B14: =I10*B13 -> 0.6768 | I14: =J10*B13 -> 1.7235
A16: SAAS SCENARIO
A17: Users/month | B17: 100 | C17: Projects/user | D17: 2
A18: Monthly API cost | B18: =I10*B17*D17 -> 45.12
A19: Subscription rev ($99/u) | B19: =B17*99 -> 9900
A20: API Gross Margin | B20: =1-B18/B19 -> 0.99544242
A21: Net margin (w/ $2K infra) | B21: =1-(B18+2000)/B19 -> 0.79342222

Sheet Framework Map
A1: # | B1: Framework | C1: Category | D1: P0 | E1: P1 | F1: P1b | G1: P2 | H1: P3 | I1: P3b | J1: P4 | K1: P5 | L1: Total
A2: 1 | B2: STEELMAN | C2: Stress Test | F2: ✓ | L2: =COUNTIF(D2:K2,"✓") -> 1
A3: 2 | B3: PREMORTEM | C3: Stress Test | F3: ✓ | L3: =COUNTIF(D3:K3,"✓") -> 1
A4: 3 | B4: DOUBLE_CRUX | C4: Stress Test | E4: ✓ | F4: ✓ | L4: =COUNTIF(D4:K4,"✓") -> 2
A5: 4 | B5: BAYES_LITE | C5: Bayesian | D5: ✓ | E5: ✓ | F5: ✓ | L5: =COUNTIF(D5:K5,"✓") -> 3
A6: 5 | B6: PROBABILISTIC_SCENARIO | C6: Bayesian | E6: ✓ | H6: ✓ | L6: =COUNTIF(D6:K6,"✓") -> 2
A7: 6 | B7: EXPECTED_VALUE | C7: Bayesian | H7: ✓ | L7: =COUNTIF(D7:K7,"✓") -> 1
A8: 7 | B8: VOI | C8: Bayesian | G8: ✓ | L8: =COUNTIF(D8:K8,"✓") -> 1
A9: 8 | B9: THOMPSON_SAMPLING | C9: Bayesian | G9: ✓ | L9: =COUNTIF(D9:K9,"✓") -> 1
A10: 9 | B10: FMEA | C10: Risk | G10: ✓ | L10: =COUNTIF(D10:K10,"✓") -> 1
A11: 10 | B11: REAL_OPTIONS | C11: Risk | H11: ✓ | L11: =COUNTIF(D11:K11,"✓") -> 1
A12: 11 | B12: REGRET_MINIMIZATION | C12: Risk | H12: ✓ | L12: =COUNTIF(D12:K12,"✓") -> 1
A13: 12 | B13: ENBS | C13: Risk | G13: ✓ | L13: =COUNTIF(D13:K13,"✓") -> 1
A14: 13 | B14: SENSEMAKING | C14: Strategic | D14: ✓ | L14: =COUNTIF(D14:K14,"✓") -> 1
A15: 14 | B15: CYNEFIN | C15: Strategic | D15: ✓ | L15: =COUNTIF(D15:K15,"✓") -> 1
A16: 15 | B16: OODA | C16: Strategic | D16: ✓ | L16: =COUNTIF(D16:K16,"✓") -> 1
A17: 16 | B17: MECE | C17: Structural | E17: ✓ | L17: =COUNTIF(D17:K17,"✓") -> 1
A18: 17 | B18: ISSUE_TREE | C18: Structural | E18: ✓ | L18: =COUNTIF(D18:K18,"✓") -> 1
A19: 18 | B19: FIVE_FORCES | C19: Competitive | H19: ✓ | L19: =COUNTIF(D19:K19,"✓") -> 1
A20: 19 | B20: SWOT | C20: Competitive | H20: ✓ | L20: =COUNTIF(D20:K20,"✓") -> 1
A21: 20 | B21: REQUISITE_VARIETY | C21: Systems | D21: ✓ | L21: =COUNTIF(D21:K21,"✓") -> 1
A22: 21 | B22: SYSTEMS_DYNAMICS | C22: Systems | J22: ✓ | L22: =COUNTIF(D22:K22,"✓") -> 1
A23: 22 | B23: STAKEHOLDER_MAPPING | C23: Social | H23: ✓ | L23: =COUNTIF(D23:K23,"✓") -> 1
A24: 23 | B24: DELPHI | C24: Social | I24: ✓ | L24: =COUNTIF(D24:K24,"✓") -> 1
A25: 24 | B25: DQ_SPIDER | C25: Quality | I25: ✓ | L25: =COUNTIF(D25:K25,"✓") -> 1
A26: 25 | B26: DECISION_JOURNAL | C26: Quality | K26: ✓ | L26: =COUNTIF(D26:K26,"✓") -> 1
A27: 26 | B27: BRIER_SCORING | C27: Calibration | J27: ✓ | L27: =COUNTIF(D27:K27,"✓") -> 1
A28: 27 | B28: CALIBRATION_TRAINING | C28: Calibration | J28: ✓ | L28: =COUNTIF(D28:K28,"✓") -> 1
A29: 28 | B29: MONTE_CARLO | C29: Simulation | E29: ✓ | L29: =COUNTIF(D29:K29,"✓") -> 1
A30: 29 | B30: SENSITIVITY | C30: Simulation | H30: ✓ | L30: =COUNTIF(D30:K30,"✓") -> 1
A31: 30 | B31: SISTEMICO_RELACIONAL | C31: Systems | H31: ✓ | L31: =COUNTIF(D31:K31,"✓") -> 1
A33: CATEGORY SUMMARY
B34: Stress Test | C34: =COUNTIF(C2:C31,B34) -> 3
B35: Bayesian | C35: =COUNTIF(C2:C31,B35) -> 5
B36: Risk | C36: =COUNTIF(C2:C31,B36) -> 4
B37: Strategic | C37: =COUNTIF(C2:C31,B37) -> 3
B38: Structural | C38: =COUNTIF(C2:C31,B38) -> 2
B39: Competitive | C39: =COUNTIF(C2:C31,B39) -> 2
B40: Systems | C40: =COUNTIF(C2:C31,B40) -> 3
B41: Social | C41: =COUNTIF(C2:C31,B41) -> 2
...

Sheet Gates
A1: Gate | B1: Phase | C1: Min Conf | D1: BF | E1: DQ Min | F1: Required Fields | G1: Retries | H1: Python Logic
A2: G0 | B2: P0: Classify | C2: 0.7 | D2: 10 | E2: 60 | F2: domain, bf, variety_gaps, ooda, dq | G2: 2 | H2: bf >= 10 and dq["frame"] >= 60
A3: G1 | B3: P1: Hypotheses | C3: 0.7 | D3: N/A | E3: 60 | F3: hypotheses (≥3), sealed=true | G3: 2 | H3: len(hyps) >= 3 and sealed
A4: G2 | B4: P2: Audit | C4: 0.65 | D4: N/A | E4: N/A | F4: fmea (≥1), top_findings (≥1) | G4: 2 | H4: len(fmea) >= 1
A5: G3 | B5: P3: Strategy | C5: 0.6 | D5: N/A | E5: N/A | F5: strategies (≥1), verdicts (≥1) | G5: 2 | H5: len(strategies) >= 1
A6: G4 | B6: P4: Monitor | C6: 0.6 | D6: N/A | E6: N/A | F6: tracking_plan, checkpoints | G6: 2 | H6: tracking_plan is not None
A7: G5 | B7: P5: Report | C7: 0.6 | D7: N/A | E7: N/A | F7: narrative, appendices | G7: 1 | H7: narrative is not None

Sheet Re-entry
A1: Trigger | B1: Condition | C1: Target Phase | D1: Detection | E1: Auto/Manual | F1: Invalidates | G1: Severity
A2: R1 | B2: Assumption >2σ | C2: P1: Hypotheses | D2: Posterior vs prior | E2: Auto | F2: P1→P5 | G2: High
A3: R2 | B3: Domain reclassified | C3: P0: Classify | D3: Cynefin shift | E3: Auto | F3: P0→P5 | G3: Critical
A4: R3 | B4: Scope change >30% | C4: P0: Classify | D4: Brief diff | E4: Manual | F4: P0→P5 | G4: Critical
A5: R4 | B5: Portfolio ρ>0.5 | C5: P1: Hypotheses | D5: Gauntlet ρ | E5: Auto | F5: P1→P5 | G5: High
A6: R5 | B6: SQI <60 on strategy | C6: P3: Strategy | D6: SQI output | E6: Auto | F6: P3→P5 | G6: High
A7: R6 | B7: External data invalidates | C7: P2: Audit | D7: Data feed | E7: Manual | F7: P2→P5 | G7: Medium
A8: R7 | B8: Stakeholder change | C8: P1: Hypotheses | D8: DQ re-score | E8: Manual | F8: P1→P5 | G8: Medium
A9: R8 | B9: Deadline exceeded | C9: P4: Monitor | D9: Timer | E9: Auto | F9: Current→P5 | G9: Low

Sheet Invalidation
A1: Source | B1: Invalidated Outputs | C1: Count
A2: brief | B2: classify, hypotheses, gauntlet, audit, strategy, sqi, monitor, report | C2: =IF(B2="(none)",0,LEN(B2)-LEN(SUBSTITUTE(B2,",",""))+1) -> 8
A3: data | B3: audit, strategy, sqi | C3: =IF(B3="(none)",0,LEN(B3)-LEN(SUBSTITUTE(B3,",",""))+1) -> 3
A4: P0: Classify | B4: hypotheses, gauntlet, audit, strategy, sqi, monitor, report | C4: =IF(B4="(none)",0,LEN(B4)-LEN(SUBSTITUTE(B4,",",""))+1) -> 7
A5: P1: Hypotheses | B5: gauntlet, audit, strategy, sqi, monitor, report | C5: =IF(B5="(none)",0,LEN(B5)-LEN(SUBSTITUTE(B5,",",""))+1) -> 6
A6: P2: Audit | B6: strategy, sqi, monitor, report | C6: =IF(B6="(none)",0,LEN(B6)-LEN(SUBSTITUTE(B6,",",""))+1) -> 4
A7: P3: Strategy | B7: sqi, monitor, report | C7: =IF(B7="(none)",0,LEN(B7)-LEN(SUBSTITUTE(B7,",",""))+1) -> 3
A8: P4: Monitor | B8: report | C8: =IF(B8="(none)",0,LEN(B8)-LEN(SUBSTITUTE(B8,",",""))+1) -> 1
A9: P5: Report | B9: (none) | C9: =IF(B9="(none)",0,LEN(B9)-LEN(SUBSTITUTE(B9,",",""))+1) -> 0

Sheet Meta-Learning
A1: META-LEARNING TRACKER
A3: PREDICTION CALIBRATION (50 slots)
A4: Project | B4: Hypothesis | C4: Phase | D4: Predicted P | E4: Actual (0/1) | F4: Squared Error | G4: Framework | H4: Confidence Bin
F5: =IF(AND(D5<>"",E5<>""),(D5-E5)^2,"") | H5: =IF(D5="","",FLOOR(D5,0.1))
F6: =IF(AND(D6<>"",E6<>""),(D6-E6)^2,"") | H6: =IF(D6="","",FLOOR(D6,0.1))
F7: =IF(AND(D7<>"",E7<>""),(D7-E7)^2,"") | H7: =IF(D7="","",FLOOR(D7,0.1))
F8: =IF(AND(D8<>"",E8<>""),(D8-E8)^2,"") | H8: =IF(D8="","",FLOOR(D8,0.1))
F9: =IF(AND(D9<>"",E9<>""),(D9-E9)^2,"") | H9: =IF(D9="","",FLOOR(D9,0.1))
F10: =IF(AND(D10<>"",E10<>""),(D10-E10)^2,"") | H10: =IF(D10="","",FLOOR(D10,0.1))
F11: =IF(AND(D11<>"",E11<>""),(D11-E11)^2,"") | H11: =IF(D11="","",FLOOR(D11,0.1))
F12: =IF(AND(D12<>"",E12<>""),(D12-E12)^2,"") | H12: =IF(D12="","",FLOOR(D12,0.1))
F13: =IF(AND(D13<>"",E13<>""),(D13-E13)^2,"") | H13: =IF(D13="","",FLOOR(D13,0.1))
F14: =IF(AND(D14<>"",E14<>""),(D14-E14)^2,"") | H14: =IF(D14="","",FLOOR(D14,0.1))
F15: =IF(AND(D15<>"",E15<>""),(D15-E15)^2,"") | H15: =IF(D15="","",FLOOR(D15,0.1))
F16: =IF(AND(D16<>"",E16<>""),(D16-E16)^2,"") | H16: =IF(D16="","",FLOOR(D16,0.1))
... F54: =IF(AND(D54<>"",E54<>""),(D54-E54)^2,"") | H54: =IF(D54="","",FLOOR(D54,0.1))
A56: CALIBRATION SUMMARY
A57: Total Predictions | B57: =COUNT(F5:F54) -> 0
A58: Brier Score (lower=better) | B58: =IFERROR(AVERAGE(F5:F54),"-") -> -
A59: Perfect calibration | B59: 0
A60: Random baseline | B60: 0.25
A61: Skill Score | B61: =IFERROR(1-B58/0.25,"-") -> -
A63: FRAMEWORK EFFECTIVENESS
A64: Framework | B64: Uses | C64: Avg Brier | D64: Contribution
B65: =COUNTIF(G5:G54,A65) -> 0 | C65: =IFERROR(AVERAGEIF(G5:G54,A65,F5:F54),"-") -> - | D65: =IFERROR(C65/B$58,"")
B66: =COUNTIF(G5:G54,A66) -> 0 | C66: =IFERROR(AVERAGEIF(G5:G54,A66,F5:F54),"-") -> - | D66: =IFERROR(C66/B$58,"")
B67: =COUNTIF(G5:G54,A67) -> 0 | C67: =IFERROR(AVERAGEIF(G5:G54,A67,F5:F54),"-") -> - | D67: =IFERROR(C67/B$58,"")
B68: =COUNTIF(G5:G54,A68) -> 0 | C68: =IFERROR(AVERAGEIF(G5:G54,A68,F5:F54),"-") -> - | D68: =IFERROR(C68/B$58,"")
B69: =COUNTIF(G5:G54,A69) -> 0 | C69: =IFERROR(AVERAGEIF(G5:G54,A69,F5:F54),"-") -> - | D69: =IFERROR(C69/B$58,"")
B70: =COUNTIF(G5:G54,A70) -> 0 | C70: =IFERROR(AVERAGEIF(G5:G54,A70,F5:F54),"-") -> - | D70: =IFERROR(C70/B$58,"")
B71: =COUNTIF(G5:G54,A71) -> 0 | C71: =IFERROR(AVERAGEIF(G5:G54,A71,F5:F54),"-") -> - | D71: =IFERROR(C71/B$58,"")
B72: =COUNTIF(G5:G54,A72) -> 0 | C72: =IFERROR(AVERAGEIF(G5:G54,A72,F5:F54),"-") -> - | D72: =IFERROR(C72/B$58,"")
B73: =COUNTIF(G5:G54,A73) -> 0 | C73: =IFERROR(AVERAGEIF(G5:G54,A73,F5:F54),"-") -> - | D73: =IFERROR(C73/B$58,"")
B74: =COUNTIF(G5:G54,A74) -> 0 | C74: =IFERROR(AVERAGEIF(G5:G54,A74,F5:F54),"-") -> - | D74: =IFERROR(C74/B$58,"")

Sheet Project Log
A1: # | B1: Project | C1: Domain | D1: Start | E1: End | F1: Days | G1: Phases | H1: Re-entries | I1: Revenue | J1: API Cost | K1: Net Margin | L1: Status | M1: Client
A2: 1 | F2: =IF(AND(D2<>"",E2<>""),E2-D2,"") | J2: =IF(I2<>"",'Cost Model'!I10,"") | K2: =IF(AND(I2<>"",J2<>""),1-J2/I2,"")
A3: 2 | F3: =IF(AND(D3<>"",E3<>""),E3-D3,"") | J3: =IF(I3<>"",'Cost Model'!I10,"") | K3: =IF(AND(I3<>"",J3<>""),1-J3/I3,"")
A4: 3 | F4: =IF(AND(D4<>"",E4<>""),E4-D4,"") | J4: =IF(I4<>"",'Cost Model'!I10,"") | K4: =IF(AND(I4<>"",J4<>""),1-J4/I4,"")
A5: 4 | F5: =IF(AND(D5<>"",E5<>""),E5-D5,"") | J5: =IF(I5<>"",'Cost Model'!I10,"") | K5: =IF(AND(I5<>"",J5<>""),1-J5/I5,"")
A6: 5 | F6: =IF(AND(D6<>"",E6<>""),E6-D6,"") | J6: =IF(I6<>"",'Cost Model'!I10,"") | K6: =IF(AND(I6<>"",J6<>""),1-J6/I6,"")
A7: 6 | F7: =IF(AND(D7<>"",E7<>""),E7-D7,"") | J7: =IF(I7<>"",'Cost Model'!I10,"") | K7: =IF(AND(I7<>"",J7<>""),1-J7/I7,"")
A8: 7 | F8: =IF(AND(D8<>"",E8<>""),E8-D8,"") | J8: =IF(I8<>"",'Cost Model'!I10,"") | K8: =IF(AND(I8<>"",J8<>""),1-J8/I8,"")
A9: 8 | F9: =IF(AND(D9<>"",E9<>""),E9-D9,"") | J9: =IF(I9<>"",'Cost Model'!I10,"") | K9: =IF(AND(I9<>"",J9<>""),1-J9/I9,"")
A10: 9 | F10: =IF(AND(D10<>"",E10<>""),E10-D10,"") | J10: =IF(I10<>"",'Cost Model'!I10,"") | K10: =IF(AND(I10<>"",J10<>""),1-J10/I10,"")
A11: 10 | F11: =IF(AND(D11<>"",E11<>""),E11-D11,"") | J11: =IF(I11<>"",'Cost Model'!I10,"") | K11: =IF(AND(I11<>"",J11<>""),1-J11/I11,"")
A12: 11 | F12: =IF(AND(D12<>"",E12<>""),E12-D12,"") | J12: =IF(I12<>"",'Cost Model'!I10,"") | K12: =IF(AND(I12<>"",J12<>""),1-J12/I12,"")
A13: 12 | F13: =IF(AND(D13<>"",E13<>""),E13-D13,"") | J13: =IF(I13<>"",'Cost Model'!I10,"") | K13: =IF(AND(I13<>"",J13<>""),1-J13/I13,"")
A14: 13 | F14: =IF(AND(D14<>"",E14<>""),E14-D14,"") | J14: =IF(I14<>"",'Cost Model'!I10,"") | K14: =IF(AND(I14<>"",J14<>""),1-J14/I14,"")
A15: 14 | F15: =IF(AND(D15<>"",E15<>""),E15-D15,"") | J15: =IF(I15<>"",'Cost Model'!I10,"") | K15: =IF(AND(I15<>"",J15<>""),1-J15/I15,"")
A16: 15 | F16: =IF(AND(D16<>"",E16<>""),E16-D16,"") | J16: =IF(I16<>"",'Cost Model'!I10,"") | K16: =IF(AND(I16<>"",J16<>""),1-J16/I16,"")
A17: 16 | F17: =IF(AND(D17<>"",E17<>""),E17-D17,"") | J17: =IF(I17<>"",'Cost Model'!I10,"") | K17: =IF(AND(I17<>"",J17<>""),1-J17/I17,"")
A18: 17 | F18: =IF(AND(D18<>"",E18<>""),E18-D18,"") | J18: =IF(I18<>"",'Cost Model'!I10,"") | K18: =IF(AND(I18<>"",J18<>""),1-J18/I18,"")
A19: 18 | F19: =IF(AND(D19<>"",E19<>""),E19-D19,"") | J19: =IF(I19<>"",'Cost Model'!I10,"") | K19: =IF(AND(I19<>"",J19<>""),1-J19/I19,"")
A20: 19 | F20: =IF(AND(D20<>"",E20<>""),E20-D20,"") | J20: =IF(I20<>"",'Cost Model'!I10,"") | K20: =IF(AND(I20<>"",J20<>""),1-J20/I20,"")
A21: 20 | F21: =IF(AND(D21<>"",E21<>""),E21-D21,"") | J21: =IF(I21<>"",'Cost Model'!I10,"") | K21: =IF(AND(I21<>"",J21<>""),1-J21/I21,"")
A22: 21 | F22: =IF(AND(D22<>"",E22<>""),E22-D22,"") | J22: =IF(I22<>"",'Cost Model'!I10,"") | K22: =IF(AND(I22<>"",J22<>""),1-J22/I22,"")
A23: 22 | F23: =IF(AND(D23<>"",E23<>""),E23-D23,"") | J23: =IF(I23<>"",'Cost Model'!I10,"") | K23: =IF(AND(I23<>"",J23<>""),1-J23/I23,"")
A24: 23 | F24: =IF(AND(D24<>"",E24<>""),E24-D24,"") | J24: =IF(I24<>"",'Cost Model'!I10,"") | K24: =IF(AND(I24<>"",J24<>""),1-J24/I24,"")
A25: 24 | F25: =IF(AND(D25<>"",E25<>""),E25-D25,"") | J25: =IF(I25<>"",'Cost Model'!I10,"") | K25: =IF(AND(I25<>"",J25<>""),1-J25/I25,"")
A26: 25 | F26: =IF(AND(D26<>"",E26<>""),E26-D26,"") | J26: =IF(I26<>"",'Cost Model'!I10,"") | K26: =IF(AND(I26<>"",J26<>""),1-J26/I26,"")
A27: 26 | F27: =IF(AND(D27<>"",E27<>""),E27-D27,"") | J27: =IF(I27<>"",'Cost Model'!I10,"") | K27: =IF(AND(I27<>"",J27<>""),1-J27/I27,"")
A28: 27 | F28: =IF(AND(D28<>"",E28<>""),E28-D28,"") | J28: =IF(I28<>"",'Cost Model'!I10,"") | K28: =IF(AND(I28<>"",J28<>""),1-J28/I28,"")
A29: 28 | F29: =IF(AND(D29<>"",E29<>""),E29-D29,"") | J29: =IF(I29<>"",'Cost Model'!I10,"") | K29: =IF(AND(I29<>"",J29<>""),1-J29/I29,"")
A30: 29 | F30: =IF(AND(D30<>"",E30<>""),E30-D30,"") | J30: =IF(I30<>"",'Cost Model'!I10,"") | K30: =IF(AND(I30<>"",J30<>""),1-J30/I30,"")
A31: 30 | F31: =IF(AND(D31<>"",E31<>""),E31-D31,"") | J31: =IF(I31<>"",'Cost Model'!I10,"") | K31: =IF(AND(I31<>"",J31<>""),1-J31/I31,"")
A33: SUMMARY
A34: Total projects | B34: =COUNTA(B2:B31) -> 0
A35: Avg days | B35: =IFERROR(AVERAGE(F2:F31),"-") -> -
A36: Total revenue | B36: =SUM(I2:I31) -> 0
A37: Total API cost | B37: =SUM(J2:J31) -> 0
A38: Avg margin | B38: =IFERROR(1-B37/B36,"-") -> -

Sheet Pipeline
A1: Company | B1: Contact | C1: Source | D1: First Touch | E1: Last Touch | F1: Stage | G1: Deal Value | H1: Probability | I1: Next Action | J1: Close Date
A53: PIPELINE SUMMARY
A54: Stage | B54: Count | C54: Value | D54: Weighted
A55: Lead | B55: =COUNTIF(F2:F51,A55) -> 0 | C55: =SUMIF(F2:F51,A55,G2:G51) -> 0 | D55: =SUMPRODUCT((F2:F51=A55)*G2:G51*H2:H51) -> 0
A56: Outreach | B56: =COUNTIF(F2:F51,A56) -> 0 | C56: =SUMIF(F2:F51,A56,G2:G51) -> 0 | D56: =SUMPRODUCT((F2:F51=A56)*G2:G51*H2:H51) -> 0
A57: Discovery | B57: =COUNTIF(F2:F51,A57) -> 0 | C57: =SUMIF(F2:F51,A57,G2:G51) -> 0 | D57: =SUMPRODUCT((F2:F51=A57)*G2:G51*H2:H51) -> 0
A58: Proposal | B58: =COUNTIF(F2:F51,A58) -> 0 | C58: =SUMIF(F2:F51,A58,G2:G51) -> 0 | D58: =SUMPRODUCT((F2:F51=A58)*G2:G51*H2:H51) -> 0
A59: Negotiation | B59: =COUNTIF(F2:F51,A59) -> 0 | C59: =SUMIF(F2:F51,A59,G2:G51) -> 0 | D59: =SUMPRODUCT((F2:F51=A59)*G2:G51*H2:H51) -> 0
A60: Won | B60: =COUNTIF(F2:F51,A60) -> 0 | C60: =SUMIF(F2:F51,A60,G2:G51) -> 0 | D60: =SUMPRODUCT((F2:F51=A60)*G2:G51*H2:H51) -> 0
A61: Lost | B61: =COUNTIF(F2:F51,A61) -> 0 | C61: =SUMIF(F2:F51,A61,G2:G51) -> 0 | D61: =SUMPRODUCT((F2:F51=A61)*G2:G51*H2:H51) -> 0
A62: Total pipeline | C62: =SUM(C55:C61) -> 0 | D62: =SUM(D55:D61) -> 0
A64: CONVERSION RATES
A65: Lead → Discovery | B65: =IFERROR((B57+B58+B59+B60+B61)/(B55+B56+B57+B58+B59+B60+B61),"-") -> -
A66: Discovery → Proposal | B66: =IFERROR((B58+B59+B60+B61)/(B57+B58+B59+B60+B61),"-") -> -
A67: Proposal → Won | B67: =IFERROR(B60/(B58+B59+B60+B61),"-") -> -
A68: Overall Win Rate | B68: =IFERROR(B60/(B60+B61),"-") -> -

Sheet Revenue Forecast
A1: 12-MONTH REVENUE FORECAST & P&L
B3: M1 | C3: M2 | D3: M3 | E3: M4 | F3: M5 | G3: M6 | H3: M7 | I3: M8 | J3: M9 | K3: M10 | L3: M11 | M3: M12 | N3: TOTAL
A4: REVENUE
A5: Consulting projects | B5: 2000 | C5: 4000 | D5: 5500 | E5: 6000 | F5: 7000 | G5: 8000 | H5: 8000 | I5: 9000 | J5: 9000 | K5: 10000 | L5: 10000 | M5: 10000 | N5: =SUM(B5:M5) -> 88500
A6: Monthly retainers | B6: 0 | C6: 0 | D6: 2000 | E6: 2500 | F6: 3000 | G6: 3500 | H6: 4000 | I6: 4500 | J6: 5000 | K6: 5500 | L6: 6000 | M6: 6500 | N6: =SUM(B6:M6) -> 42500
A7: Expert network calls | B7: 0 | C7: 500 | D7: 750 | E7: 800 | F7: 800 | G7: 800 | H7: 1000 | I7: 1000 | J7: 1000 | K7: 1000 | L7: 1000 | M7: 1000 | N7: =SUM(B7:M7) -> 9650
A8: Platform work (Upwork) | B8: 0 | C8: 250 | D8: 400 | E8: 300 | F8: 200 | G8: 100 | H8: 0 | I8: 0 | J8: 0 | K8: 0 | L8: 0 | M8: 0 | N8: =SUM(B8:M8) -> 1250
A9: TOTAL REVENUE | B9: =SUM(B5:B8) -> 2000 | C9: =SUM(C5:C8) -> 4750 | D9: =SUM(D5:D8) -> 8650 | E9: =SUM(E5:E8) -> 9600 | F9: =SUM(F5:F8) -> 11000 | G9: =SUM(G5:G8) -> 12400 | H9: =SUM(H5:H8) -> 13000 | I9: =SUM(I5:I8) -> 14500 | ... M9: =SUM(M5:M8) -> 17500 | N9: =SUM(B9:M9) -> 141900
A11: COSTS
A12: API costs (Anthropic/OpenAI) | B12: 50 | C12: 100 | D12: 150 | E12: 200 | F12: 250 | G12: 300 | H12: 350 | I12: 400 | J12: 400 | K12: 400 | L12: 400 | M12: 400 | N12: =SUM(B12:M12) -> 3400
A13: LinkedIn Sales Navigator | B13: 110 | C13: 110 | D13: 110 | E13: 110 | F13: 110 | G13: 110 | H13: 110 | I13: 110 | J13: 110 | K13: 110 | L13: 110 | M13: 110 | N13: =SUM(B13:M13) -> 1320
A14: Cold email tools | B14: 0 | C14: 30 | D14: 60 | E14: 60 | F14: 60 | G14: 60 | H14: 60 | I14: 60 | J14: 60 | K14: 60 | L14: 60 | M14: 60 | N14: =SUM(B14:M14) -> 630
A15: Wise + Stripe fees | B15: 10 | C15: 25 | D15: 50 | E15: 60 | F15: 70 | G15: 80 | H15: 80 | I15: 90 | J15: 90 | K15: 100 | L15: 100 | M15: 100 | N15: =SUM(B15:M15) -> 855
A16: LLC + registered agent | B16: 510 | C16: 10 | D16: 10 | E16: 10 | F16: 10 | G16: 10 | H16: 10 | I16: 10 | J16: 10 | K16: 10 | L16: 10 | M16: 10 | N16: =SUM(B16:M16) -> 620
A17: CPA / accounting | B17: 0 | C17: 0 | D17: 100 | E17: 0 | F17: 0 | G17: 100 | H17: 0 | I17: 0 | J17: 100 | K17: 0 | L17: 0 | M17: 300 | N17: =SUM(B17:M17) -> 600
A18: Health insurance | B18: 200 | C18: 200 | D18: 200 | E18: 200 | F18: 200 | G18: 200 | H18: 200 | I18: 200 | J18: 200 | K18: 200 | L18: 200 | M18: 200 | N18: =SUM(B18:M18) -> 2400
A19: Software (Zoom, CRM, etc.) | B19: 40 | C19: 40 | D19: 40 | E19: 40 | F19: 40 | G19: 40 | H19: 40 | I19: 40 | J19: 40 | K19: 40 | L19: 40 | M19: 40 | N19: =SUM(B19:M19) -> 480
A20: VA (from month 4) | B20: 0 | C20: 0 | D20: 0 | E20: 600 | F20: 600 | G20: 600 | H20: 600 | I20: 600 | J20: 600 | K20: 600 | L20: 600 | M20: 600 | N20: =SUM(B20:M20) -> 5400
A21: TOTAL COSTS | B21: =SUM(B12:B20) -> 920 | C21: =SUM(C12:C20) -> 515 | D21: =SUM(D12:D20) -> 720 | E21: =SUM(E12:E20) -> 1280 | F21: =SUM(F12:F20) -> 1340 | G21: =SUM(G12:G20) -> 1500 | H21: =SUM(H12:H20) -> 1450 | I21: =SUM(I12:I20) -> 1510 | ... M21: =SUM(M12:M20) -> 1820 | N21: =SUM(B21:M21) -> 15705
A23: NET INCOME | B23: =B9-B21 -> 1080 | C23: =C9-C21 -> 4235 | D23: =D9-D21 -> 7930 | E23: =E9-E21 -> 8320 | F23: =F9-F21 -> 9660 | G23: =G9-G21 -> 10900 | H23: =H9-H21 -> 11550 | I23: =I9-I21 -> 12990 | ... M23: =M9-M21 -> 15680 | N23: =SUM(B23:M23) -> 126195
A24: Net Margin % | B24: =IFERROR(B23/B9,"-") -> 0.54 | C24: =IFERROR(C23/C9,"-") -> 0.89157895 | D24: =IFERROR(D23/D9,"-") -> 0.91676301 | E24: =IFERROR(E23/E9,"-") -> 0.86666667 | F24: =IFERROR(F23/F9,"-") -> 0.87818182 | G24: =IFERROR(G23/G9,"-") -> 0.87903226 | H24: =IFERROR(H23/H9,"-") -> 0.88846154 | I24: =IFERROR(I23/I9,"-") -> 0.89586207 | ... N24: =IFERROR(N23/N9,"-") -> 0.88932347
A26: CUMULATIVE CASH | B26: =B23 -> 1080 | C26: =B26+C23 -> 5315 | D26: =C26+D23 -> 13245 | E26: =D26+E23 -> 21565 | F26: =E26+F23 -> 31225 | G26: =F26+G23 -> 42125 | H26: =G26+H23 -> 53675 | I26: =H26+I23 -> 66665 | J26: =I26+J23 -> 80055 | ... M26: =L26+M23 -> 126195

Sheet Assumptions
A1: ASSUMPTIONS & DATA SOURCES
A3: Assumption | B3: Value | C3: Source | D3: Date Verified
A4: Claude Opus 4.6 input price | B4: $5.00/MTok | C4: platform.claude.com/docs/en/about-claude/pricing | D4: Apr 2026
A5: Claude Opus 4.6 output price | B5: $25.00/MTok | C5: platform.claude.com/docs/en/about-claude/pricing | D5: Apr 2026
A6: Claude Sonnet 4.6 input price | B6: $3.00/MTok | C6: platform.claude.com/docs/en/about-claude/pricing | D6: Apr 2026
A7: Claude Sonnet 4.6 output price | B7: $15.00/MTok | C7: platform.claude.com/docs/en/about-claude/pricing | D7: Apr 2026
A8: Claude Haiku 4.5 input price | B8: $1.00/MTok | C8: platform.claude.com/docs/en/about-claude/pricing | D8: Apr 2026
A9: Claude Haiku 4.5 output price | B9: $5.00/MTok | C9: platform.claude.com/docs/en/about-claude/pricing | D9: Apr 2026
A10: Cache read discount | B10: 90% | C10: Anthropic docs — cache_control: ephemeral | D10: Apr 2026
A11: Batch API discount | B11: 50% | C11: Anthropic docs — batch processing | D11: Apr 2026
A12: LinkedIn connection limit (free) | B12: ~100/week | C12: Konnector, Cleverly 2026 benchmarks | D12: Apr 2026
A13: LinkedIn connection limit (Sales Nav) | B13: 150-250/week | C13: Konnector, LinkedSDR 2026 | D13: Apr 2026
A14: LinkedIn acceptance rate | B14: 30-45% | C14: Cleverly 2026, Botdog study (16,492 requests) | D14: Apr 2026
... A32: LangGraph version | B32: 1.0 GA | C32: changelog.langchain.com — Oct 22, 2025 | D32: Oct 2025
